let n = 12
try {
    const n = 11
} catch {
    console.log("An error occured")
}

console.log(n)